Workbook
Name Slicer_Customer_Type: #N/A
Name Slicer_Service: #N/A
Name Slicer_Year: #N/A

Sheet Dashboard

Sheet Input Data
A1: Country | B1: Year | C1: Service | D1: Customer Type | E1: Revenue | F1: Gross Profit | G1: EBITDA
A2: USA | B2: 2018 | C2: Artificial Intelligence | D2: SMB | E2: =INDEX('Financials USA'!$E$7:$N$19,MATCH(_xlfn.CONCAT('Input Data'!D2,'Input Data'!C2),'Financials USA'!$A$7:$A$19,0),MATCH('Input Data'!B2,'Financials USA'!$E$1:$N$1,0)) -> 1869 | F2: =VLOOKUP(_xlfn.CONCAT(A2,B2,C2),'Gross Profit & EBITDA'!$D$2:$F$61,2,FALSE)*E2 -> 934.5 | G2: =VLOOKUP(_xlfn.CONCAT(A2,B2,C2),'Gross Profit & EBITDA'!$D$2:$F$61,3,FALSE)*E2 -> 373.8 | I2: Customer Type | J2: (All)
A3: USA | B3: 2018 | C3: Artificial Intelligence | D3: Enterprise | E3: =INDEX('Financials USA'!$E$7:$N$19,MATCH(_xlfn.CONCAT('Input Data'!D3,'Input Data'!C3),'Financials USA'!$A$7:$A$19,0),MATCH('Input Data'!B3,'Financials USA'!$E$1:$N$1,0)) -> 23961 | F3: =VLOOKUP(_xlfn.CONCAT(A3,B3,C3),'Gross Profit & EBITDA'!$D$2:$F$61,2,FALSE)*E3 -> 11980.5 | G3: =VLOOKUP(_xlfn.CONCAT(A3,B3,C3),'Gross Profit & EBITDA'!$D$2:$F$61,3,FALSE)*E3 -> 4792.2 | I3: Service | J3: (All)
A4: USA | B4: 2018 | C4: Marketing | D4: SMB | E4: =INDEX('Financials USA'!$E$7:$N$19,MATCH(_xlfn.CONCAT('Input Data'!D4,'Input Data'!C4),'Financials USA'!$A$7:$A$19,0),MATCH('Input Data'!B4,'Financials USA'!$E$1:$N$1,0)) -> 5607 | F4: =VLOOKUP(_xlfn.CONCAT(A4,B4,C4),'Gross Profit & EBITDA'!$D$2:$F$61,2,FALSE)*E4 -> 3924.9 | G4: =VLOOKUP(_xlfn.CONCAT(A4,B4,C4),'Gross Profit & EBITDA'!$D$2:$F$61,3,FALSE)*E4 -> 1121.4
A5: USA | B5: 2018 | C5: Marketing | D5: Enterprise | E5: =INDEX('Financials USA'!$E$7:$N$19,MATCH(_xlfn.CONCAT('Input Data'!D5,'Input Data'!C5),'Financials USA'!$A$7:$A$19,0),MATCH('Input Data'!B5,'Financials USA'!$E$1:$N$1,0)) -> 23961 | F5: =VLOOKUP(_xlfn.CONCAT(A5,B5,C5),'Gross Profit & EBITDA'!$D$2:$F$61,2,FALSE)*E5 -> 16772.7 | G5: =VLOOKUP(_xlfn.CONCAT(A5,B5,C5),'Gross Profit & EBITDA'!$D$2:$F$61,3,FALSE)*E5 -> 4792.2 | I5: Row Labels | J5: Sum of Revenue | K5: Sum of EBITDA
A6: USA | B6: 2018 | C6: Accounting | D6: SMB | E6: =INDEX('Financials USA'!$E$7:$N$19,MATCH(_xlfn.CONCAT('Input Data'!D6,'Input Data'!C6),'Financials USA'!$A$7:$A$19,0),MATCH('Input Data'!B6,'Financials USA'!$E$1:$N$1,0)) -> 684 | F6: =VLOOKUP(_xlfn.CONCAT(A6,B6,C6),'Gross Profit & EBITDA'!$D$2:$F$61,2,FALSE)*E6 -> 478.8 | G6: =VLOOKUP(_xlfn.CONCAT(A6,B6,C6),'Gross Profit & EBITDA'!$D$2:$F$61,3,FALSE)*E6 -> 68.4 | I6: 2018 | J6: 172710 | K6: 31368.4
A7: USA | B7: 2018 | C7: Accounting | D7: Enterprise | E7: =INDEX('Financials USA'!$E$7:$N$19,MATCH(_xlfn.CONCAT('Input Data'!D7,'Input Data'!C7),'Financials USA'!$A$7:$A$19,0),MATCH('Input Data'!B7,'Financials USA'!$E$1:$N$1,0)) -> 9098 | F7: =VLOOKUP(_xlfn.CONCAT(A7,B7,C7),'Gross Profit & EBITDA'!$D$2:$F$61,2,FALSE)*E7 -> 6368.6 | G7: =VLOOKUP(_xlfn.CONCAT(A7,B7,C7),'Gross Profit & EBITDA'!$D$2:$F$61,3,FALSE)*E7 -> 909.8 | I7: 2019 | J7: 372232 | K7: 47960.8
A8: USA | B8: 2019 | C8: Artificial Intelligence | D8: SMB | E8: =INDEX('Financials USA'!$E$7:$N$19,MATCH(_xlfn.CONCAT('Input Data'!D8,'Input Data'!C8),'Financials USA'!$A$7:$A$19,0),MATCH('Input Data'!B8,'Financials USA'!$E$1:$N$1,0)) -> 3211 | F8: =VLOOKUP(_xlfn.CONCAT(A8,B8,C8),'Gross Profit & EBITDA'!$D$2:$F$61,2,FALSE)*E8 -> 1605.5 | G8: =VLOOKUP(_xlfn.CONCAT(A8,B8,C8),'Gross Profit & EBITDA'!$D$2:$F$61,3,FALSE)*E8 -> 321.1 | I8: 2020 | J8: 253994 | K8: 44749.4
A9: USA | B9: 2019 | C9: Artificial Intelligence | D9: Enterprise | E9: =INDEX('Financials USA'!$E$7:$N$19,MATCH(_xlfn.CONCAT('Input Data'!D9,'Input Data'!C9),'Financials USA'!$A$7:$A$19,0),MATCH('Input Data'!B9,'Financials USA'!$E$1:$N$1,0)) -> 15956 | F9: =VLOOKUP(_xlfn.CONCAT(A9,B9,C9),'Gross Profit & EBITDA'!$D$2:$F$61,2,FALSE)*E9 -> 7978 | G9: =VLOOKUP(_xlfn.CONCAT(A9,B9,C9),'Gross Profit & EBITDA'!$D$2:$F$61,3,FALSE)*E9 -> 1595.6 | I9: 2021 | J9: 341092 | K9: 43972.4
A10: USA | B10: 2019 | C10: Marketing | D10: SMB | E10: =INDEX('Financials USA'!$E$7:$N$19,MATCH(_xlfn.CONCAT('Input Data'!D10,'Input Data'!C10),'Financials USA'!$A$7:$A$19,0),MATCH('Input Data'!B10,'Financials USA'!$E$1:$N$1,0)) -> 12844 | F10: =VLOOKUP(_xlfn.CONCAT(A10,B10,C10),'Gross Profit & EBITDA'!$D$2:$F$61,2,FALSE)*E10 -> 6422 | G10: =VLOOKUP(_xlfn.CONCAT(A10,B10,C10),'Gross Profit & EBITDA'!$D$2:$F$61,3,FALSE)*E10 -> 1284.4 | I10: 2022 | J10: 362808 | K10: 39367.8
A11: USA | B11: 2019 | C11: Marketing | D11: Enterprise | E11: =INDEX('Financials USA'!$E$7:$N$19,MATCH(_xlfn.CONCAT('Input Data'!D11,'Input Data'!C11),'Financials USA'!$A$7:$A$19,0),MATCH('Input Data'!B11,'Financials USA'!$E$1:$N$1,0)) -> 95736 | F11: =VLOOKUP(_xlfn.CONCAT(A11,B11,C11),'Gross Profit & EBITDA'!$D$2:$F$61,2,FALSE)*E11 -> 47868 | G11: =VLOOKUP(_xlfn.CONCAT(A11,B11,C11),'Gross Profit & EBITDA'!$D$2:$F$61,3,FALSE)*E11 -> 9573.6 | I11: 2023 | J11: 396536 | K11: 73539.2
A12: USA | B12: 2019 | C12: Accounting | D12: SMB | E12: =INDEX('Financials USA'!$E$7:$N$19,MATCH(_xlfn.CONCAT('Input Data'!D12,'Input Data'!C12),'Financials USA'!$A$7:$A$19,0),MATCH('Input Data'!B12,'Financials USA'!$E$1:$N$1,0)) -> 17682 | F12: =VLOOKUP(_xlfn.CONCAT(A12,B12,C12),'Gross Profit & EBITDA'!$D$2:$F$61,2,FALSE)*E12 -> 10609.2 | G12: =VLOOKUP(_xlfn.CONCAT(A12,B12,C12),'Gross Profit & EBITDA'!$D$2:$F$61,3,FALSE)*E12 -> 3536.4 | I12: 2024 | J12: 316422 | K12: 37103.2
A13: USA | B13: 2019 | C13: Accounting | D13: Enterprise | E13: =INDEX('Financials USA'!$E$7:$N$19,MATCH(_xlfn.CONCAT('Input Data'!D13,'Input Data'!C13),'Financials USA'!$A$7:$A$19,0),MATCH('Input Data'!B13,'Financials USA'!$E$1:$N$1,0)) -> 19683 | F13: =VLOOKUP(_xlfn.CONCAT(A13,B13,C13),'Gross Profit & EBITDA'!$D$2:$F$61,2,FALSE)*E13 -> 11809.8 | G13: =VLOOKUP(_xlfn.CONCAT(A13,B13,C13),'Gross Profit & EBITDA'!$D$2:$F$61,3,FALSE)*E13 -> 3936.6 | I13: 2025 | J13: 397088 | K13: 70410
A14: USA | B14: 2020 | C14: Artificial Intelligence | D14: SMB | E14: =INDEX('Financials USA'!$E$7:$N$19,MATCH(_xlfn.CONCAT('Input Data'!D14,'Input Data'!C14),'Financials USA'!$A$7:$A$19,0),MATCH('Input Data'!B14,'Financials USA'!$E$1:$N$1,0)) -> 4810 | F14: =VLOOKUP(_xlfn.CONCAT(A14,B14,C14),'Gross Profit & EBITDA'!$D$2:$F$61,2,FALSE)*E14 -> 3848 | G14: =VLOOKUP(_xlfn.CONCAT(A14,B14,C14),'Gross Profit & EBITDA'!$D$2:$F$61,3,FALSE)*E14 -> 962 | I14: 2026 | J14: 384896 | K14: 73763.2
A15: USA | B15: 2020 | C15: Artificial Intelligence | D15: Enterprise | E15: =INDEX('Financials USA'!$E$7:$N$19,MATCH(_xlfn.CONCAT('Input Data'!D15,'Input Data'!C15),'Financials USA'!$A$7:$A$19,0),MATCH('Input Data'!B15,'Financials USA'!$E$1:$N$1,0)) -> 16090 | F15: =VLOOKUP(_xlfn.CONCAT(A15,B15,C15),'Gross Profit & EBITDA'!$D$2:$F$61,2,FALSE)*E15 -> 12872 | G15: =VLOOKUP(_xlfn.CONCAT(A15,B15,C15),'Gross Profit & EBITDA'!$D$2:$F$61,3,FALSE)*E15 -> 3218 | I15: 2027 | J15: 447026 | K15: 81941.4
A16: USA | B16: 2020 | C16: Marketing | D16: SMB | E16: =INDEX('Financials USA'!$E$7:$N$19,MATCH(_xlfn.CONCAT('Input Data'!D16,'Input Data'!C16),'Financials USA'!$A$7:$A$19,0),MATCH('Input Data'!B16,'Financials USA'!$E$1:$N$1,0)) -> 9620 | F16: =VLOOKUP(_xlfn.CONCAT(A16,B16,C16),'Gross Profit & EBITDA'!$D$2:$F$61,2,FALSE)*E16 -> 4810 | G16: =VLOOKUP(_xlfn.CONCAT(A16,B16,C16),'Gross Profit & EBITDA'!$D$2:$F$61,3,FALSE)*E16 -> 962 | I16: Grand Total | J16: 3444804 | K16: 544175.8
A17: USA | B17: 2020 | C17: Marketing | D17: Enterprise | E17: =INDEX('Financials USA'!$E$7:$N$19,MATCH(_xlfn.CONCAT('Input Data'!D17,'Input Data'!C17),'Financials USA'!$A$7:$A$19,0),MATCH('Input Data'!B17,'Financials USA'!$E$1:$N$1,0)) -> 16090 | F17: =VLOOKUP(_xlfn.CONCAT(A17,B17,C17),'Gross Profit & EBITDA'!$D$2:$F$61,2,FALSE)*E17 -> 8045 | G17: =VLOOKUP(_xlfn.CONCAT(A17,B17,C17),'Gross Profit & EBITDA'!$D$2:$F$61,3,FALSE)*E17 -> 1609
A18: USA | B18: 2020 | C18: Accounting | D18: SMB | E18: =INDEX('Financials USA'!$E$7:$N$19,MATCH(_xlfn.CONCAT('Input Data'!D18,'Input Data'!C18),'Financials USA'!$A$7:$A$19,0),MATCH('Input Data'!B18,'Financials USA'!$E$1:$N$1,0)) -> 10140 | F18: =VLOOKUP(_xlfn.CONCAT(A18,B18,C18),'Gross Profit & EBITDA'!$D$2:$F$61,2,FALSE)*E18 -> 8112 | G18: =VLOOKUP(_xlfn.CONCAT(A18,B18,C18),'Gross Profit & EBITDA'!$D$2:$F$61,3,FALSE)*E18 -> 2028
A19: USA | B19: 2020 | C19: Accounting | D19: Enterprise | E19: =INDEX('Financials USA'!$E$7:$N$19,MATCH(_xlfn.CONCAT('Input Data'!D19,'Input Data'!C19),'Financials USA'!$A$7:$A$19,0),MATCH('Input Data'!B19,'Financials USA'!$E$1:$N$1,0)) -> 55827 | F19: =VLOOKUP(_xlfn.CONCAT(A19,B19,C19),'Gross Profit & EBITDA'!$D$2:$F$61,2,FALSE)*E19 -> 44661.6 | G19: =VLOOKUP(_xlfn.CONCAT(A19,B19,C19),'Gross Profit & EBITDA'!$D$2:$F$61,3,FALSE)*E19 -> 11165.4
A20: USA | B20: 2021 | C20: Artificial Intelligence | D20: SMB | E20: =INDEX('Financials USA'!$E$7:$N$19,MATCH(_xlfn.CONCAT('Input Data'!D20,'Input Data'!C20),'Financials USA'!$A$7:$A$19,0),MATCH('Input Data'!B20,'Financials USA'!$E$1:$N$1,0)) -> 7470 | F20: =VLOOKUP(_xlfn.CONCAT(A20,B20,C20),'Gross Profit & EBITDA'!$D$2:$F$61,2,FALSE)*E20 -> 4482 | G20: =VLOOKUP(_xlfn.CONCAT(A20,B20,C20),'Gross Profit & EBITDA'!$D$2:$F$61,3,FALSE)*E20 -> 1494
A21: USA | B21: 2021 | C21: Artificial Intelligence | D21: Enterprise | E21: =INDEX('Financials USA'!$E$7:$N$19,MATCH(_xlfn.CONCAT('Input Data'!D21,'Input Data'!C21),'Financials USA'!$A$7:$A$19,0),MATCH('Input Data'!B21,'Financials USA'!$E$1:$N$1,0)) -> 15225 | F21: =VLOOKUP(_xlfn.CONCAT(A21,B21,C21),'Gross Profit & EBITDA'!$D$2:$F$61,2,FALSE)*E21 -> 9135 | G21: =VLOOKUP(_xlfn.CONCAT(A21,B21,C21),'Gross Profit & EBITDA'!$D$2:$F$61,3,FALSE)*E21 -> 3045
A22: USA | B22: 2021 | C22: Marketing | D22: SMB | E22: =INDEX('Financials USA'!$E$7:$N$19,MATCH(_xlfn.CONCAT('Input Data'!D22,'Input Data'!C22),'Financials USA'!$A$7:$A$19,0),MATCH('Input Data'!B22,'Financials USA'!$E$1:$N$1,0)) -> 29880 | F22: =VLOOKUP(_xlfn.CONCAT(A22,B22,C22),'Gross Profit & EBITDA'!$D$2:$F$61,2,FALSE)*E22 -> 20916 | G22: =VLOOKUP(_xlfn.CONCAT(A22,B22,C22),'Gross Profit & EBITDA'!$D$2:$F$61,3,FALSE)*E22 -> 2988
A23: USA | B23: 2021 | C23: Marketing | D23: Enterprise | E23: =INDEX('Financials USA'!$E$7:$N$19,MATCH(_xlfn.CONCAT('Input Data'!D23,'Input Data'!C23),'Financials USA'!$A$7:$A$19,0),MATCH('Input Data'!B23,'Financials USA'!$E$1:$N$1,0)) -> 91350 | F23: =VLOOKUP(_xlfn.CONCAT(A23,B23,C23),'Gross Profit & EBITDA'!$D$2:$F$61,2,FALSE)*E23 -> 63945 | G23: =VLOOKUP(_xlfn.CONCAT(A23,B23,C23),'Gross Profit & EBITDA'!$D$2:$F$61,3,FALSE)*E23 -> 9135 | I23: Year | J23: (All)
A24: USA | B24: 2021 | C24: Accounting | D24: SMB | E24: =INDEX('Financials USA'!$E$7:$N$19,MATCH(_xlfn.CONCAT('Input Data'!D24,'Input Data'!C24),'Financials USA'!$A$7:$A$19,0),MATCH('Input Data'!B24,'Financials USA'!$E$1:$N$1,0)) -> 3252 | F24: =VLOOKUP(_xlfn.CONCAT(A24,B24,C24),'Gross Profit & EBITDA'!$D$2:$F$61,2,FALSE)*E24 -> 2601.6 | G24: =VLOOKUP(_xlfn.CONCAT(A24,B24,C24),'Gross Profit & EBITDA'!$D$2:$F$61,3,FALSE)*E24 -> 650.4 | I24: Customer Type | J24: (All)
A25: USA | B25: 2021 | C25: Accounting | D25: Enterprise | E25: =INDEX('Financials USA'!$E$7:$N$19,MATCH(_xlfn.CONCAT('Input Data'!D25,'Input Data'!C25),'Financials USA'!$A$7:$A$19,0),MATCH('Input Data'!B25,'Financials USA'!$E$1:$N$1,0)) -> 6756 | F25: =VLOOKUP(_xlfn.CONCAT(A25,B25,C25),'Gross Profit & EBITDA'!$D$2:$F$61,2,FALSE)*E25 -> 5404.8 | G25: =VLOOKUP(_xlfn.CONCAT(A25,B25,C25),'Gross Profit & EBITDA'!$D$2:$F$61,3,FALSE)*E25 -> 1351.2
A26: USA | B26: 2022 | C26: Artificial Intelligence | D26: SMB | E26: =INDEX('Financials USA'!$E$7:$N$19,MATCH(_xlfn.CONCAT('Input Data'!D26,'Input Data'!C26),'Financials USA'!$A$7:$A$19,0),MATCH('Input Data'!B26,'Financials USA'!$E$1:$N$1,0)) -> 11367 | F26: =VLOOKUP(_xlfn.CONCAT(A26,B26,C26),'Gross Profit & EBITDA'!$D$2:$F$61,2,FALSE)*E26 -> 7956.9 | G26: =VLOOKUP(_xlfn.CONCAT(A26,B26,C26),'Gross Profit & EBITDA'!$D$2:$F$61,3,FALSE)*E26 -> 1136.7 | I26: Row Labels | J26: Revenue | K26: Gross Profit | L26: EBITDA
A27: USA | B27: 2022 | C27: Artificial Intelligence | D27: Enterprise | E27: =INDEX('Financials USA'!$E$7:$N$19,MATCH(_xlfn.CONCAT('Input Data'!D27,'Input Data'!C27),'Financials USA'!$A$7:$A$19,0),MATCH('Input Data'!B27,'Financials USA'!$E$1:$N$1,0)) -> 14484 | F27: =VLOOKUP(_xlfn.CONCAT(A27,B27,C27),'Gross Profit & EBITDA'!$D$2:$F$61,2,FALSE)*E27 -> 10138.8 | G27: =VLOOKUP(_xlfn.CONCAT(A27,B27,C27),'Gross Profit & EBITDA'!$D$2:$F$61,3,FALSE)*E27 -> 1448.4 | I27: Accounting | J27: 766694 | K27: 497113.8 | L27: 131267
A28: USA | B28: 2022 | C28: Marketing | D28: SMB | E28: =INDEX('Financials USA'!$E$7:$N$19,MATCH(_xlfn.CONCAT('Input Data'!D28,'Input Data'!C28),'Financials USA'!$A$7:$A$19,0),MATCH('Input Data'!B28,'Financials USA'!$E$1:$N$1,0)) -> 22734 | F28: =VLOOKUP(_xlfn.CONCAT(A28,B28,C28),'Gross Profit & EBITDA'!$D$2:$F$61,2,FALSE)*E28 -> 11367 | G28: =VLOOKUP(_xlfn.CONCAT(A28,B28,C28),'Gross Profit & EBITDA'!$D$2:$F$61,3,FALSE)*E28 -> 2273.4 | I28: Artificial Intelligence | J28: 701974 | K28: 416295 | L28: 114326.6
A29: USA | B29: 2022 | C29: Marketing | D29: Enterprise | E29: =INDEX('Financials USA'!$E$7:$N$19,MATCH(_xlfn.CONCAT('Input Data'!D29,'Input Data'!C29),'Financials USA'!$A$7:$A$19,0),MATCH('Input Data'!B29,'Financials USA'!$E$1:$N$1,0)) -> 86904 | F29: =VLOOKUP(_xlfn.CONCAT(A29,B29,C29),'Gross Profit & EBITDA'!$D$2:$F$61,2,FALSE)*E29 -> 43452 | G29: =VLOOKUP(_xlfn.CONCAT(A29,B29,C29),'Gross Profit & EBITDA'!$D$2:$F$61,3,FALSE)*E29 -> 8690.4 | I29: Marketing | J29: 1976136 | K29: 1161788.4 | L29: 298582.2
A30: USA | B30: 2022 | C30: Accounting | D30: SMB | E30: =INDEX('Financials USA'!$E$7:$N$19,MATCH(_xlfn.CONCAT('Input Data'!D30,'Input Data'!C30),'Financials USA'!$A$7:$A$19,0),MATCH('Input Data'!B30,'Financials USA'!$E$1:$N$1,0)) -> 3515 | F30: =VLOOKUP(_xlfn.CONCAT(A30,B30,C30),'Gross Profit & EBITDA'!$D$2:$F$61,2,FALSE)*E30 -> 2812 | G30: =VLOOKUP(_xlfn.CONCAT(A30,B30,C30),'Gross Profit & EBITDA'!$D$2:$F$61,3,FALSE)*E30 -> 351.5 | I30: Grand Total | J30: 3444804 | K30: 2075197.2 | L30: 544175.8
A31: USA | B31: 2022 | C31: Accounting | D31: Enterprise | E31: =INDEX('Financials USA'!$E$7:$N$19,MATCH(_xlfn.CONCAT('Input Data'!D31,'Input Data'!C31),'Financials USA'!$A$7:$A$19,0),MATCH('Input Data'!B31,'Financials USA'!$E$1:$N$1,0)) -> 18760 | F31: =VLOOKUP(_xlfn.CONCAT(A31,B31,C31),'Gross Profit & EBITDA'!$D$2:$F$61,2,FALSE)*E31 -> 15008 | G31: =VLOOKUP(_xlfn.CONCAT(A31,B31,C31),'Gross Profit & EBITDA'!$D$2:$F$61,3,FALSE)*E31 -> 1876
A32: USA | B32: 2023 | C32: Artificial Intelligence | D32: SMB | E32: =INDEX('Financials USA'!$E$7:$N$19,MATCH(_xlfn.CONCAT('Input Data'!D32,'Input Data'!C32),'Financials USA'!$A$7:$A$19,0),MATCH('Input Data'!B32,'Financials USA'!$E$1:$N$1,0)) -> 6894 | F32: =VLOOKUP(_xlfn.CONCAT(A32,B32,C32),'Gross Profit & EBITDA'!$D$2:$F$61,2,FALSE)*E32 -> 4825.8 | G32: =VLOOKUP(_xlfn.CONCAT(A32,B32,C32),'Gross Profit & EBITDA'!$D$2:$F$61,3,FALSE)*E32 -> 1378.8
A33: USA | B33: 2023 | C33: Artificial Intelligence | D33: Enterprise | E33: =INDEX('Financials USA'!$E$7:$N$19,MATCH(_xlfn.CONCAT('Input Data'!D33,'Input Data'!C33),'Financials USA'!$A$7:$A$19,0),MATCH('Input Data'!B33,'Financials USA'!$E$1:$N$1,0)) -> 18660 | F33: =VLOOKUP(_xlfn.CONCAT(A33,B33,C33),'Gross Profit & EBITDA'!$D$2:$F$61,2,FALSE)*E33 -> 13062 | G33: =VLOOKUP(_xlfn.CONCAT(A33,B33,C33),'Gross Profit & EBITDA'!$D$2:$F$61,3,FALSE)*E33 -> 3732
A34: USA | B34: 2023 | C34: Marketing | D34: SMB | E34: =INDEX('Financials USA'!$E$7:$N$19,MATCH(_xlfn.CONCAT('Input Data'!D34,'Input Data'!C34),'Financials USA'!$A$7:$A$19,0),MATCH('Input Data'!B34,'Financials USA'!$E$1:$N$1,0)) -> 13788 | F34: =VLOOKUP(_xlfn.CONCAT(A34,B34,C34),'Gross Profit & EBITDA'!$D$2:$F$61,2,FALSE)*E34 -> 9651.6 | G34: =VLOOKUP(_xlfn.CONCAT(A34,B34,C34),'Gross Profit & EBITDA'!$D$2:$F$61,3,FALSE)*E34 -> 2757.6 | I34: Year | J34: (All)
A35: USA | B35: 2023 | C35: Marketing | D35: Enterprise | E35: =INDEX('Financials USA'!$E$7:$N$19,MATCH(_xlfn.CONCAT('Input Data'!D35,'Input Data'!C35),'Financials USA'!$A$7:$A$19,0),MATCH('Input Data'!B35,'Financials USA'!$E$1:$N$1,0)) -> 111960 | F35: =VLOOKUP(_xlfn.CONCAT(A35,B35,C35),'Gross Profit & EBITDA'!$D$2:$F$61,2,FALSE)*E35 -> 78372 | G35: =VLOOKUP(_xlfn.CONCAT(A35,B35,C35),'Gross Profit & EBITDA'!$D$2:$F$61,3,FALSE)*E35 -> 22392 | I35: Service | J35: (All)
A36: USA | B36: 2023 | C36: Accounting | D36: SMB | E36: =INDEX('Financials USA'!$E$7:$N$19,MATCH(_xlfn.CONCAT('Input Data'!D36,'Input Data'!C36),'Financials USA'!$A$7:$A$19,0),MATCH('Input Data'!B36,'Financials USA'!$E$1:$N$1,0)) -> 5064 | F36: =VLOOKUP(_xlfn.CONCAT(A36,B36,C36),'Gross Profit & EBITDA'!$D$2:$F$61,2,FALSE)*E36 -> 4051.2 | G36: =VLOOKUP(_xlfn.CONCAT(A36,B36,C36),'Gross Profit & EBITDA'!$D$2:$F$61,3,FALSE)*E36 -> 506.4 | I36: Customer Type | J36: (All)
A37: USA | B37: 2023 | C37: Accounting | D37: Enterprise | E37: =INDEX('Financials USA'!$E$7:$N$19,MATCH(_xlfn.CONCAT('Input Data'!D37,'Input Data'!C37),'Financials USA'!$A$7:$A$19,0),MATCH('Input Data'!B37,'Financials USA'!$E$1:$N$1,0)) -> 15933 | F37: =VLOOKUP(_xlfn.CONCAT(A37,B37,C37),'Gross Profit & EBITDA'!$D$2:$F$61,2,FALSE)*E37 -> 12746.4 | G37: =VLOOKUP(_xlfn.CONCAT(A37,B37,C37),'Gross Profit & EBITDA'!$D$2:$F$61,3,FALSE)*E37 -> 1593.3
A38: USA | B38: 2024 | C38: Artificial Intelligence | D38: SMB | E38: =INDEX('Financials USA'!$E$7:$N$19,MATCH(_xlfn.CONCAT('Input Data'!D38,'Input Data'!C38),'Financials USA'!$A$7:$A$19,0),MATCH('Input Data'!B38,'Financials USA'!$E$1:$N$1,0)) -> 8880 | F38: =VLOOKUP(_xlfn.CONCAT(A38,B38,C38),'Gross Profit & EBITDA'!$D$2:$F$61,2,FALSE)*E38 -> 4440 | G38: =VLOOKUP(_xlfn.CONCAT(A38,B38,C38),'Gross Profit & EBITDA'!$D$2:$F$61,3,FALSE)*E38 -> 1776 | I38: Sum of Revenue | J38: Sum of Gross Profit | K38: Sum of EBITDA
A39: USA | B39: 2024 | C39: Artificial Intelligence | D39: Enterprise | E39: =INDEX('Financials USA'!$E$7:$N$19,MATCH(_xlfn.CONCAT('Input Data'!D39,'Input Data'!C39),'Financials USA'!$A$7:$A$19,0),MATCH('Input Data'!B39,'Financials USA'!$E$1:$N$1,0)) -> 13958 | F39: =VLOOKUP(_xlfn.CONCAT(A39,B39,C39),'Gross Profit & EBITDA'!$D$2:$F$61,2,FALSE)*E39 -> 6979 | G39: =VLOOKUP(_xlfn.CONCAT(A39,B39,C39),'Gross Profit & EBITDA'!$D$2:$F$61,3,FALSE)*E39 -> 2791.6 | I39: 3444804 | J39: 2075197.2 | K39: 544175.8
A40: USA | B40: 2024 | C40: Marketing | D40: SMB | E40: =INDEX('Financials USA'!$E$7:$N$19,MATCH(_xlfn.CONCAT('Input Data'!D40,'Input Data'!C40),'Financials USA'!$A$7:$A$19,0),MATCH('Input Data'!B40,'Financials USA'!$E$1:$N$1,0)) -> 53280 | F40: =VLOOKUP(_xlfn.CONCAT(A40,B40,C40),'Gross Profit & EBITDA'!$D$2:$F$61,2,FALSE)*E40 -> 26640 | G40: =VLOOKUP(_xlfn.CONCAT(A40,B40,C40),'Gross Profit & EBITDA'!$D$2:$F$61,3,FALSE)*E40 -> 5328
...

Sheet Financials USA
D1: Year | E1: 2018 | F1: 2019 | G1: 2020 | H1: 2021 | I1: 2022 | J1: 2023 | K1: 2024 | L1: 2025 | M1: 2026 | N1: 2027
D2: Period start | F2: 43466 | G2: 43831 | H2: 44197 | I2: 44562 | J2: 44927 | K2: 45292 | L2: 45658 | M2: 46023 | N2: 46388
D3: Period end | E3: 43465 | F3: 43830 | G3: 44196 | H3: 44561 | I3: 44926 | J3: 45291 | K3: 45657 | L3: 46022 | M3: 46387 | N3: 46752
A6: Index Key | B6: Customer | C6: Service
A7: =_xlfn.CONCAT(B7,C7) -> SMBArtificial Intelligence | B7: SMB | C7: Artificial Intelligence | E7: 1869 | F7: 3211 | G7: 4810 | H7: 7470 | I7: 11367 | J7: 6894 | K7: 8880 | L7: 4901 | M7: 3828 | N7: 5424
A8: =_xlfn.CONCAT(B8,C8) -> EnterpriseArtificial Intelligence | B8: Enterprise | C8: Artificial Intelligence | E8: 23961 | F8: 15956 | G8: 16090 | H8: 15225 | I8: 14484 | J8: 18660 | K8: 13958 | L8: 26427 | M8: 24219 | N8: 23442
C9: Total | E9: =SUM(E7:E8) -> 25830 | F9: =SUM(F7:F8) -> 19167 | G9: =SUM(G7:G8) -> 20900 | H9: =SUM(H7:H8) -> 22695 | I9: =SUM(I7:I8) -> 25851 | J9: =SUM(J7:J8) -> 25554 | K9: =SUM(K7:K8) -> 22838 | L9: =SUM(L7:L8) -> 31328 | ... N9: =SUM(N7:N8) -> 28866
A12: =_xlfn.CONCAT(B12,C12) -> SMBMarketing | B12: SMB | C12: Marketing | E12: 5607 | F12: 12844 | G12: 9620 | H12: 29880 | I12: 22734 | J12: 13788 | K12: 53280 | L12: 14703 | M12: 3828 | N12: 5424
A13: =_xlfn.CONCAT(B13,C13) -> EnterpriseMarketing | B13: Enterprise | C13: Marketing | E13: 23961 | F13: 95736 | G13: 16090 | H13: 91350 | I13: 86904 | J13: 111960 | K13: 41874 | L13: 52854 | M13: 96876 | N13: 140652
C14: Total | E14: =SUM(E12:E13) -> 29568 | F14: =SUM(F12:F13) -> 108580 | G14: =SUM(G12:G13) -> 25710 | H14: =SUM(H12:H13) -> 121230 | I14: =SUM(I12:I13) -> 109638 | J14: =SUM(J12:J13) -> 125748 | K14: =SUM(K12:K13) -> 95154 | L14: =SUM(L12:L13) -> 67557 | ... N14: =SUM(N12:N13) -> 146076
A18: =_xlfn.CONCAT(B18,C18) -> SMBAccounting | B18: SMB | C18: Accounting | E18: 684 | F18: 17682 | G18: 10140 | H18: 3252 | I18: 3515 | J18: 5064 | K18: 9666 | L18: 1365 | M18: 3022 | N18: 15468
A19: =_xlfn.CONCAT(B19,C19) -> EnterpriseAccounting | B19: Enterprise | C19: Accounting | E19: 9098 | F19: 19683 | G19: 55827 | H19: 6756 | I19: 18760 | J19: 15933 | K19: 6528 | L19: 68814 | M19: 32694 | N19: 9172
C20: Total | E20: =SUM(E18:E19) -> 9782 | F20: =SUM(F18:F19) -> 37365 | G20: =SUM(G18:G19) -> 65967 | H20: =SUM(H18:H19) -> 10008 | I20: =SUM(I18:I19) -> 22275 | J20: =SUM(J18:J19) -> 20997 | K20: =SUM(K18:K19) -> 16194 | L20: =SUM(L18:L19) -> 70179 | ... N20: =SUM(N18:N19) -> 24640
B23: Total Revenue | E23: =SUM(E9,E14,E20) -> 65180 | F23: =SUM(F9,F14,F20) -> 165112 | G23: =SUM(G9,G14,G20) -> 112577 | H23: =SUM(H9,H14,H20) -> 153933 | I23: =SUM(I9,I14,I20) -> 157764 | J23: =SUM(J9,J14,J20) -> 172299 | K23: =SUM(K9,K14,K20) -> 134186 | L23: =SUM(L9,L14,L20) -> 169064 | ... N23: =SUM(N9,N14,N20) -> 199582

Sheet Financials Canada
D1: Year | E1: 2018 | F1: 2019 | G1: 2020 | H1: 2021 | I1: 2022 | J1: 2023 | K1: 2024 | L1: 2025 | M1: 2026 | N1: 2027
D2: Period start | F2: 43466 | G2: 43831 | H2: 44197 | I2: 44562 | J2: 44927 | K2: 45292 | L2: 45658 | M2: 46023 | N2: 46388
D3: Period end | E3: 43465 | F3: 43830 | G3: 44196 | H3: 44561 | I3: 44926 | J3: 45291 | K3: 45657 | L3: 46022 | M3: 46387 | N3: 46752
A6: Index Key | B6: Customer | C6: Service
A7: =_xlfn.CONCAT(B7,C7) -> SMBArtificial Intelligence | B7: SMB | C7: Artificial Intelligence | E7: 1869 | F7: 3211 | G7: 2405 | H7: 2490 | I7: 3789 | J7: 2298 | K7: 4440 | L7: 4901 | M7: 3828 | N7: 1808
A8: =_xlfn.CONCAT(B8,C8) -> EnterpriseArtificial Intelligence | B8: Enterprise | C8: Artificial Intelligence | E8: 7987 | F8: 7978 | G8: 8045 | H8: 5075 | I8: 7242 | J8: 9330 | K8: 6979 | L8: 8809 | M8: 8073 | N8: 7814
C9: Total | E9: =SUM(E7:E8) -> 9856 | F9: =SUM(F7:F8) -> 11189 | G9: =SUM(G7:G8) -> 10450 | H9: =SUM(H7:H8) -> 7565 | I9: =SUM(I7:I8) -> 11031 | J9: =SUM(J7:J8) -> 11628 | K9: =SUM(K7:K8) -> 11419 | L9: =SUM(L7:L8) -> 13710 | ... N9: =SUM(N7:N8) -> 9622
A12: =_xlfn.CONCAT(B12,C12) -> SMBMarketing | B12: SMB | C12: Marketing | E12: 2184 | F12: 1395 | G12: 1625 | H12: 1710 | I12: 1738 | J12: 2471 | K12: 1689 | L12: 2300 | M12: 3500 | N12: 2150
A13: =_xlfn.CONCAT(B13,C13) -> EnterpriseMarketing | B13: Enterprise | C13: Marketing | E13: 3902 | F13: 3286 | G13: 2912 | H13: 4586 | I13: 2666 | J13: 4027 | K13: 2778 | L13: 5369 | M13: 4109 | N13: 3706
C14: Total | E14: =SUM(E12:E13) -> 6086 | F14: 4682 | G14: 4537 | H14: 6296 | I14: 4404 | J14: 6498 | K14: 4467 | L14: 7670 | M14: 6610 | N14: 5856
A18: =_xlfn.CONCAT(B18,C18) -> SMBAccounting | B18: SMB | C18: Accounting | E18: 684 | F18: 2947 | G18: 1690 | H18: 1626 | I18: 3515 | J18: 2532 | K18: 1611 | L18: 455 | M18: 3022 | N18: 3867
A19: =_xlfn.CONCAT(B19,C19) -> EnterpriseAccounting | B19: Enterprise | C19: Accounting | E19: 4549 | F19: 2187 | G19: 6203 | H19: 1126 | I19: 4690 | J19: 5311 | K19: 6528 | L19: 7646 | M19: 5449 | N19: 4586
C20: Total | E20: =SUM(E18:E19) -> 5233 | F20: =SUM(F18:F19) -> 5134 | G20: =SUM(G18:G19) -> 7893 | H20: =SUM(H18:H19) -> 2752 | I20: =SUM(I18:I19) -> 8205 | J20: =SUM(J18:J19) -> 7843 | K20: =SUM(K18:K19) -> 8139 | L20: =SUM(L18:L19) -> 8101 | ... N20: =SUM(N18:N19) -> 8453
B23: Total Revenue | E23: =SUM(E9,E14,E20) -> 21175 | F23: =SUM(F9,F14,F20) -> 21005 | G23: =SUM(G9,G14,G20) -> 22880 | H23: =SUM(H9,H14,H20) -> 16613 | I23: =SUM(I9,I14,I20) -> 23640 | J23: =SUM(J9,J14,J20) -> 25969 | K23: =SUM(K9,K14,K20) -> 24025 | L23: =SUM(L9,L14,L20) -> 29481 | ... N23: =SUM(N9,N14,N20) -> 23931

Sheet Gross Profit & EBITDA
A1: Country | B1: Year | C1: Service | D1: Index Key | E1: Gross Profit Margin | F1: EBITDA Margin
A2: USA | B2: 2018 | C2: Artificial Intelligence | D2: =_xlfn.CONCAT(A2,B2,C2) -> USA2018Artificial Intelligence | E2: 0.5 | F2: 0.2
A3: USA | B3: 2019 | C3: Artificial Intelligence | D3: =_xlfn.CONCAT(A3,B3,C3) -> USA2019Artificial Intelligence | E3: 0.5 | F3: 0.1
A4: USA | B4: 2020 | C4: Artificial Intelligence | D4: =_xlfn.CONCAT(A4,B4,C4) -> USA2020Artificial Intelligence | E4: 0.8 | F4: 0.2
A5: USA | B5: 2021 | C5: Artificial Intelligence | D5: =_xlfn.CONCAT(A5,B5,C5) -> USA2021Artificial Intelligence | E5: 0.6 | F5: 0.2
A6: USA | B6: 2022 | C6: Artificial Intelligence | D6: =_xlfn.CONCAT(A6,B6,C6) -> USA2022Artificial Intelligence | E6: 0.7 | F6: 0.1
A7: USA | B7: 2023 | C7: Artificial Intelligence | D7: =_xlfn.CONCAT(A7,B7,C7) -> USA2023Artificial Intelligence | E7: 0.7 | F7: 0.2
A8: USA | B8: 2024 | C8: Artificial Intelligence | D8: =_xlfn.CONCAT(A8,B8,C8) -> USA2024Artificial Intelligence | E8: 0.5 | F8: 0.2
A9: USA | B9: 2025 | C9: Artificial Intelligence | D9: =_xlfn.CONCAT(A9,B9,C9) -> USA2025Artificial Intelligence | E9: 0.6 | F9: 0.1
A10: USA | B10: 2026 | C10: Artificial Intelligence | D10: =_xlfn.CONCAT(A10,B10,C10) -> USA2026Artificial Intelligence | E10: 0.5 | F10: 0.2
A11: USA | B11: 2027 | C11: Artificial Intelligence | D11: =_xlfn.CONCAT(A11,B11,C11) -> USA2027Artificial Intelligence | E11: 0.5 | F11: 0.1
A12: USA | B12: 2018 | C12: Marketing | D12: =_xlfn.CONCAT(A12,B12,C12) -> USA2018Marketing | E12: 0.7 | F12: 0.2
A13: USA | B13: 2019 | C13: Marketing | D13: =_xlfn.CONCAT(A13,B13,C13) -> USA2019Marketing | E13: 0.5 | F13: 0.1
... A61: Canada | B61: 2027 | C61: Accounting | D61: =_xlfn.CONCAT(A61,B61,C61) -> Canada2027Accounting | E61: 0.6 | F61: 0.1
